<sdf version='1.6'>
  <world name='default'>
    <plugin name="hello" filename="libhello.so"/>
    <light name='sun' type='directional'>
      <cast_shadows>1</cast_shadows>
      <pose frame=''>0 0 10 0 -0 0</pose>
      <diffuse>0.8 0.8 0.8 1</diffuse>
      <specular>0.2 0.2 0.2 1</specular>
      <attenuation>
        <range>1000</range>
        <constant>0.9</constant>
        <linear>0.01</linear>
        <quadratic>0.001</quadratic>
      </attenuation>
      <direction>-0.5 0.1 -0.9</direction>
    </light>
    <model name='ground_plane'>
      <static>1</static>
      <link name='link'>
        <collision name='collision'>
          <geometry>
            <plane>
              <normal>0 0 1</normal>
              <size>100 100</size>
            </plane>
          </geometry>
          <surface>
            <contact>
              <collide_bitmask>65535</collide_bitmask>
              <ode/>
            </contact>
            <friction>
              <ode>
                <mu>100</mu>
                <mu2>50</mu2>
              </ode>
              <torsional>
                <ode/>
              </torsional>
            </friction>
            <bounce/>
          </surface>
          <max_contacts>10</max_contacts>
        </collision>
        <visual name='visual'>
          <cast_shadows>0</cast_shadows>
          <geometry>
            <plane>
              <normal>0 0 1</normal>
              <size>100 100</size>
            </plane>
          </geometry>
          <material>
            <script>
              <uri>file://media/materials/scripts/gazebo.material</uri>
              <name>Gazebo/Grey</name>
            </script>
          </material>
        </visual>
        <self_collide>0</self_collide>
        <kinematic>0</kinematic>
      </link>
    </model>
    <gravity>0 0 -9.8</gravity>
    <magnetic_field>6e-06 2.3e-05 -4.2e-05</magnetic_field>
    <atmosphere type='adiabatic'/>
    <physics name='default_physics' default='0' type='ode'>
      <max_step_size>0.001</max_step_size>
      <real_time_factor>1</real_time_factor>
      <real_time_update_rate>1000</real_time_update_rate>
    </physics>
    <scene>
      <ambient>0.4 0.4 0.4 1</ambient>
      <background>0.7 0.7 0.7 1</background>
      <shadows>1</shadows>
    </scene>
    <spherical_coordinates>
      <surface_model>EARTH_WGS84</surface_model>
      <latitude_deg>0</latitude_deg>
      <longitude_deg>0</longitude_deg>
      <elevation>0</elevation>
      <heading_deg>0</heading_deg>
    </spherical_coordinates>
    <state world_name='default'>
      <sim_time>52 193000000</sim_time>
      <real_time>52 317677101</real_time>
      <wall_time>1624381810 444517396</wall_time>
      <iterations>52193</iterations>
      <model name='ground_plane'>
        <pose frame=''>0 0 0 0 -0 0</pose>
        <scale>1 1 1</scale>
        <link name='link'>
          <pose frame=''>0 0 0 0 -0 0</pose>
          <velocity>0 0 0 0 -0 0</velocity>
          <acceleration>0 0 0 0 -0 0</acceleration>
          <wrench>0 0 0 0 -0 0</wrench>
        </link>
      </model>
      <light name='sun'>
        <pose frame=''>0 0 10 0 -0 0</pose>
      </light>
    </state>
    <gui fullscreen='0'>
      <camera name='user_camera'>
        <pose frame=''>5 -5 2 0 0.275643 2.35619</pose>
        <view_controller>orbit</view_controller>
        <projection_type>perspective</projection_type>
      </camera>
    </gui>


    <model name='HumanoidRobot'>
    <link name='link_0'>
      <pose frame=''>0.02 0 0.1 0 -0 0</pose>
      <inertial>
        <mass>1</mass>
        <inertia>
          <ixx>0.166667</ixx>
          <ixy>0</ixy>
          <ixz>0</ixz>
          <iyy>0.166667</iyy>
          <iyz>0</iyz>
          <izz>0.166667</izz>
        </inertia>
        <pose frame=''>0 0 0 0 -0 0</pose>
      </inertial>
      <gravity>1</gravity>
      <self_collide>0</self_collide>
      <kinematic>0</kinematic>
      <visual name='visual'>
        <pose frame=''>0 0 0 0 -0 0</pose>
        <geometry>
          <box>
            <size>0.4 0.2 0.1</size>
          </box>
        </geometry>
        <material>
          <lighting>1</lighting>
          <script>
            <uri>file://media/materials/scripts/gazebo.material</uri>
            <name>Gazebo/Grey</name>
          </script>
          <shader type='pixel'>
            <normal_map>__default__</normal_map>
          </shader>
          <ambient>0.3 0.3 0.3 1</ambient>
          <diffuse>0.7 0.7 0.7 1</diffuse>
          <specular>0.01 0.01 0.01 1</specular>
          <emissive>0 0 0 1</emissive>
        </material>
        <transparency>0</transparency>
        <cast_shadows>1</cast_shadows>
      </visual>
      <collision name='collision'>
        <laser_retro>0</laser_retro>
        <max_contacts>10</max_contacts>
        <pose frame=''>0 0 0 0 -0 0</pose>
        <geometry>
          <box>
            <size>0.4 0.2 0.1</size>
          </box>
        </geometry>
        <surface>
          <friction>
            <ode>
              <mu>1</mu>
              <mu2>1</mu2>
              <fdir1>0 0 0</fdir1>
              <slip1>0</slip1>
              <slip2>0</slip2>
            </ode>
            <torsional>
              <coefficient>1</coefficient>
              <patch_radius>0</patch_radius>
              <surface_radius>0</surface_radius>
              <use_patch_radius>1</use_patch_radius>
              <ode>
                <slip>0</slip>
              </ode>
            </torsional>
          </friction>
          <bounce>
            <restitution_coefficient>0</restitution_coefficient>
            <threshold>1e+06</threshold>
          </bounce>
          <contact>
            <collide_without_contact>0</collide_without_contact>
            <collide_without_contact_bitmask>1</collide_without_contact_bitmask>
            <collide_bitmask>1</collide_bitmask>
            <ode>
              <soft_cfm>0</soft_cfm>
              <soft_erp>0.2</soft_erp>
              <kp>1e+13</kp>
              <kd>1</kd>
              <max_vel>0.01</max_vel>
              <min_depth>0</min_depth>
            </ode>
            <bullet>
              <split_impulse>1</split_impulse>
              <split_impulse_penetration_threshold>-0.01</split_impulse_penetration_threshold>
              <soft_cfm>0</soft_cfm>
              <soft_erp>0.2</soft_erp>
              <kp>1e+13</kp>
              <kd>1</kd>
            </bullet>
          </contact>
        </surface>
      </collision>
    </link>
    <link name='link_1'>
      <pose frame=''>0.12 0.13 0.1 0.000335 1.5707 1.57046</pose>
      <inertial>
        <mass>1</mass>
        <inertia>
          <ixx>0.145833</ixx>
          <ixy>0</ixy>
          <ixz>0</ixz>
          <iyy>0.145833</iyy>
          <iyz>0</iyz>
          <izz>0.125</izz>
        </inertia>
        <pose frame=''>0 0 0 0 -0 0</pose>
      </inertial>
      <gravity>1</gravity>
      <self_collide>0</self_collide>
      <kinematic>0</kinematic>
      <visual name='visual'>
        <pose frame=''>0 0 0 0 -0 0</pose>
        <geometry>
          <cylinder>
            <radius>0.1</radius>
            <length>0.05</length>
          </cylinder>
        </geometry>
        <material>
          <lighting>1</lighting>
          <script>
            <uri>file://media/materials/scripts/gazebo.material</uri>
            <name>Gazebo/Grey</name>
          </script>
          <shader type='pixel'>
            <normal_map>__default__</normal_map>
          </shader>
          <ambient>0.3 0.3 0.3 1</ambient>
          <diffuse>0.7 0.7 0.7 1</diffuse>
          <specular>0.01 0.01 0.01 1</specular>
          <emissive>0 0 0 1</emissive>
        </material>
        <transparency>0</transparency>
        <cast_shadows>1</cast_shadows>
      </visual>
      <collision name='collision'>
        <laser_retro>0</laser_retro>
        <max_contacts>10</max_contacts>
        <pose frame=''>0 0 0 0 -0 0</pose>
        <geometry>
          <cylinder>
            <radius>0.1</radius>
            <length>0.05</length>
          </cylinder>
        </geometry>
        <surface>
          <friction>
            <ode>
              <mu>1</mu>
              <mu2>1</mu2>
              <fdir1>0 0 0</fdir1>
              <slip1>0</slip1>
              <slip2>0</slip2>
            </ode>
            <torsional>
              <coefficient>1</coefficient>
              <patch_radius>0</patch_radius>
              <surface_radius>0</surface_radius>
              <use_patch_radius>1</use_patch_radius>
              <ode>
                <slip>0</slip>
              </ode>
            </torsional>
          </friction>
          <bounce>
            <restitution_coefficient>0</restitution_coefficient>
            <threshold>1e+06</threshold>
          </bounce>
          <contact>
            <collide_without_contact>0</collide_without_contact>
            <collide_without_contact_bitmask>1</collide_without_contact_bitmask>
            <collide_bitmask>1</collide_bitmask>
            <ode>
              <soft_cfm>0</soft_cfm>
              <soft_erp>0.2</soft_erp>
              <kp>1e+13</kp>
              <kd>1</kd>
              <max_vel>0.01</max_vel>
              <min_depth>0</min_depth>
            </ode>
            <bullet>
              <split_impulse>1</split_impulse>
              <split_impulse_penetration_threshold>-0.01</split_impulse_penetration_threshold>
              <soft_cfm>0</soft_cfm>
              <soft_erp>0.2</soft_erp>
              <kp>1e+13</kp>
              <kd>1</kd>
            </bullet>
          </contact>
        </surface>
      </collision>
    </link>
    <link name='link_1_clone'>
      <pose frame=''>0.12 -0.13 0.1 0.000427 1.5707 1.57037</pose>
      <inertial>
        <mass>1</mass>
        <inertia>
          <ixx>0.145833</ixx>
          <ixy>0</ixy>
          <ixz>0</ixz>
          <iyy>0.145833</iyy>
          <iyz>0</iyz>
          <izz>0.125</izz>
        </inertia>
        <pose frame=''>0 0 0 0 -0 0</pose>
      </inertial>
      <self_collide>0</self_collide>
      <kinematic>0</kinematic>
      <gravity>1</gravity>
      <visual name='visual'>
        <pose frame=''>0 0 0 0 -0 0</pose>
        <geometry>
          <cylinder>
            <radius>0.1</radius>
            <length>0.05</length>
          </cylinder>
        </geometry>
        <material>
          <lighting>1</lighting>
          <script>
            <uri>file://media/materials/scripts/gazebo.material</uri>
            <name>Gazebo/Grey</name>
          </script>
          <shader type='pixel'>
            <normal_map>__default__</normal_map>
          </shader>
          <ambient>0.3 0.3 0.3 1</ambient>
          <diffuse>0.7 0.7 0.7 1</diffuse>
          <specular>0.01 0.01 0.01 1</specular>
          <emissive>0 0 0 1</emissive>
        </material>
        <transparency>0</transparency>
        <cast_shadows>1</cast_shadows>
      </visual>
      <collision name='collision'>
        <laser_retro>0</laser_retro>
        <max_contacts>10</max_contacts>
        <pose frame=''>0 0 0 0 -0 0</pose>
        <geometry>
          <cylinder>
            <radius>0.1</radius>
            <length>0.05</length>
          </cylinder>
        </geometry>
        <surface>
          <friction>
            <ode>
              <mu>1</mu>
              <mu2>1</mu2>
              <fdir1>0 0 0</fdir1>
              <slip1>0</slip1>
              <slip2>0</slip2>
            </ode>
            <torsional>
              <coefficient>1</coefficient>
              <patch_radius>0</patch_radius>
              <surface_radius>0</surface_radius>
              <use_patch_radius>1</use_patch_radius>
              <ode>
                <slip>0</slip>
              </ode>
            </torsional>
          </friction>
          <bounce>
            <restitution_coefficient>0</restitution_coefficient>
            <threshold>1e+06</threshold>
          </bounce>
          <contact>
            <collide_without_contact>0</collide_without_contact>
            <collide_without_contact_bitmask>1</collide_without_contact_bitmask>
            <collide_bitmask>1</collide_bitmask>
            <ode>
              <soft_cfm>0</soft_cfm>
              <soft_erp>0.2</soft_erp>
              <kp>1e+13</kp>
              <kd>1</kd>
              <max_vel>0.01</max_vel>
              <min_depth>0</min_depth>
            </ode>
            <bullet>
              <split_impulse>1</split_impulse>
              <split_impulse_penetration_threshold>-0.01</split_impulse_penetration_threshold>
              <soft_cfm>0</soft_cfm>
              <soft_erp>0.2</soft_erp>
              <kp>1e+13</kp>
              <kd>1</kd>
            </bullet>
          </contact>
        </surface>
      </collision>
    </link>
    <link name='link_1_clone_clone'>
      <pose frame=''>-0.13 -0.13 0.1 4.8e-05 1.5707 1.57075</pose>
      <inertial>
        <mass>1</mass>
        <inertia>
          <ixx>0.145833</ixx>
          <ixy>0</ixy>
          <ixz>0</ixz>
          <iyy>0.145833</iyy>
          <iyz>0</iyz>
          <izz>0.125</izz>
        </inertia>
        <pose frame=''>0 0 0 0 -0 0</pose>
      </inertial>
      <self_collide>0</self_collide>
      <kinematic>0</kinematic>
      <gravity>1</gravity>
      <visual name='visual'>
        <pose frame=''>0 0 0 0 -0 0</pose>
        <geometry>
          <cylinder>
            <radius>0.1</radius>
            <length>0.05</length>
          </cylinder>
        </geometry>
        <material>
          <lighting>1</lighting>
          <script>
            <uri>file://media/materials/scripts/gazebo.material</uri>
            <name>Gazebo/Grey</name>
          </script>
          <shader type='pixel'>
            <normal_map>__default__</normal_map>
          </shader>
          <ambient>0.3 0.3 0.3 1</ambient>
          <diffuse>0.7 0.7 0.7 1</diffuse>
          <specular>0.01 0.01 0.01 1</specular>
          <emissive>0 0 0 1</emissive>
        </material>
        <transparency>0</transparency>
        <cast_shadows>1</cast_shadows>
      </visual>
      <collision name='collision'>
        <laser_retro>0</laser_retro>
        <max_contacts>10</max_contacts>
        <pose frame=''>0 0 0 0 -0 0</pose>
        <geometry>
          <cylinder>
            <radius>0.1</radius>
            <length>0.05</length>
          </cylinder>
        </geometry>
        <surface>
          <friction>
            <ode>
              <mu>1</mu>
              <mu2>1</mu2>
              <fdir1>0 0 0</fdir1>
              <slip1>0</slip1>
              <slip2>0</slip2>
            </ode>
            <torsional>
              <coefficient>1</coefficient>
              <patch_radius>0</patch_radius>
              <surface_radius>0</surface_radius>
              <use_patch_radius>1</use_patch_radius>
              <ode>
                <slip>0</slip>
              </ode>
            </torsional>
          </friction>
          <bounce>
            <restitution_coefficient>0</restitution_coefficient>
            <threshold>1e+06</threshold>
          </bounce>
          <contact>
            <collide_without_contact>0</collide_without_contact>
            <collide_without_contact_bitmask>1</collide_without_contact_bitmask>
            <collide_bitmask>1</collide_bitmask>
            <ode>
              <soft_cfm>0</soft_cfm>
              <soft_erp>0.2</soft_erp>
              <kp>1e+13</kp>
              <kd>1</kd>
              <max_vel>0.01</max_vel>
              <min_depth>0</min_depth>
            </ode>
            <bullet>
              <split_impulse>1</split_impulse>
              <split_impulse_penetration_threshold>-0.01</split_impulse_penetration_threshold>
              <soft_cfm>0</soft_cfm>
              <soft_erp>0.2</soft_erp>
              <kp>1e+13</kp>
              <kd>1</kd>
            </bullet>
          </contact>
        </surface>
      </collision>
    </link>
    <link name='link_1_clone_clone_0'>
      <pose frame=''>-0.13 0.13 0.1 0.000427 1.5707 1.57037</pose>
      <inertial>
        <mass>1</mass>
        <inertia>
          <ixx>0.145833</ixx>
          <ixy>0</ixy>
          <ixz>0</ixz>
          <iyy>0.145833</iyy>
          <iyz>0</iyz>
          <izz>0.125</izz>
        </inertia>
        <pose frame=''>0 0 0 0 -0 0</pose>
      </inertial>
      <self_collide>0</self_collide>
      <kinematic>0</kinematic>
      <gravity>1</gravity>
      <visual name='visual'>
        <pose frame=''>0 0 0 0 -0 0</pose>
        <geometry>
          <cylinder>
            <radius>0.1</radius>
            <length>0.05</length>
          </cylinder>
        </geometry>
        <material>
          <lighting>1</lighting>
          <script>
            <uri>file://media/materials/scripts/gazebo.material</uri>
            <name>Gazebo/Grey</name>
          </script>
          <shader type='pixel'>
            <normal_map>__default__</normal_map>
          </shader>
          <ambient>0.3 0.3 0.3 1</ambient>
          <diffuse>0.7 0.7 0.7 1</diffuse>
          <specular>0.01 0.01 0.01 1</specular>
          <emissive>0 0 0 1</emissive>
        </material>
        <transparency>0</transparency>
        <cast_shadows>1</cast_shadows>
      </visual>
      <collision name='collision'>
        <laser_retro>0</laser_retro>
        <max_contacts>10</max_contacts>
        <pose frame=''>0 0 0 0 -0 0</pose>
        <geometry>
          <cylinder>
            <radius>0.1</radius>
            <length>0.05</length>
          </cylinder>
        </geometry>
        <surface>
          <friction>
            <ode>
              <mu>1</mu>
              <mu2>1</mu2>
              <fdir1>0 0 0</fdir1>
              <slip1>0</slip1>
              <slip2>0</slip2>
            </ode>
            <torsional>
              <coefficient>1</coefficient>
              <patch_radius>0</patch_radius>
              <surface_radius>0</surface_radius>
              <use_patch_radius>1</use_patch_radius>
              <ode>
                <slip>0</slip>
              </ode>
            </torsional>
          </friction>
          <bounce>
            <restitution_coefficient>0</restitution_coefficient>
            <threshold>1e+06</threshold>
          </bounce>
          <contact>
            <collide_without_contact>0</collide_without_contact>
            <collide_without_contact_bitmask>1</collide_without_contact_bitmask>
            <collide_bitmask>1</collide_bitmask>
            <ode>
              <soft_cfm>0</soft_cfm>
              <soft_erp>0.2</soft_erp>
              <kp>1e+13</kp>
              <kd>1</kd>
              <max_vel>0.01</max_vel>
              <min_depth>0</min_depth>
            </ode>
            <bullet>
              <split_impulse>1</split_impulse>
              <split_impulse_penetration_threshold>-0.01</split_impulse_penetration_threshold>
              <soft_cfm>0</soft_cfm>
              <soft_erp>0.2</soft_erp>
              <kp>1e+13</kp>
              <kd>1</kd>
            </bullet>
          </contact>
        </surface>
      </collision>
    </link>
    <joint name='link_0_JOINT_0' type='revolute'>
      <parent>link_0</parent>
      <child>link_1</child>
      <pose frame=''>0 0 0 0 -0 0</pose>
      <axis>
        <xyz>0 1 0</xyz>
        <use_parent_model_frame>0</use_parent_model_frame>
        <limit>
          <lower>-1.79769e+308</lower>
          <upper>1.79769e+308</upper>
          <effort>-1</effort>
          <velocity>-1</velocity>
        </limit>
        <dynamics>
          <spring_reference>0</spring_reference>
          <spring_stiffness>0</spring_stiffness>
          <damping>0</damping>
        </dynamics>
      </axis>
      <physics>
        <ode>
          <limit>
            <cfm>0</cfm>
            <erp>0.2</erp>
          </limit>
          <suspension>
            <cfm>0</cfm>
            <erp>0.2</erp>
          </suspension>
        </ode>
      </physics>
    </joint>
    <joint name='link_0_JOINT_1' type='revolute'>
      <parent>link_0</parent>
      <child>link_1_clone</child>
      <pose frame=''>0 0 0 0 -0.06 0</pose>
      <axis>
        <xyz>0 1 0</xyz>
        <use_parent_model_frame>0</use_parent_model_frame>
        <limit>
          <lower>-1.79769e+308</lower>
          <upper>1.79769e+308</upper>
          <effort>-1</effort>
          <velocity>-1</velocity>
        </limit>
        <dynamics>
          <spring_reference>0</spring_reference>
          <spring_stiffness>0</spring_stiffness>
          <damping>0</damping>
        </dynamics>
      </axis>
      <physics>
        <ode>
          <limit>
            <cfm>0</cfm>
            <erp>0.2</erp>
          </limit>
          <suspension>
            <cfm>0</cfm>
            <erp>0.2</erp>
          </suspension>
        </ode>
      </physics>
    </joint>
    <joint name='link_0_JOINT_2' type='revolute'>
      <parent>link_0</parent>
      <child>link_1_clone_clone</child>
      <pose frame=''>0 0 0 0 -0 0</pose>
      <axis>
        <xyz>0 1 0</xyz>
        <use_parent_model_frame>0</use_parent_model_frame>
        <limit>
          <lower>-1.79769e+308</lower>
          <upper>1.79769e+308</upper>
          <effort>-1</effort>
          <velocity>-1</velocity>
        </limit>
        <dynamics>
          <spring_reference>0</spring_reference>
          <spring_stiffness>0</spring_stiffness>
          <damping>0</damping>
        </dynamics>
      </axis>
      <physics>
        <ode>
          <limit>
            <cfm>0</cfm>
            <erp>0.2</erp>
          </limit>
          <suspension>
            <cfm>0</cfm>
            <erp>0.2</erp>
          </suspension>
        </ode>
      </physics>
    </joint>
    <joint name='link_0_JOINT_3' type='revolute'>
      <parent>link_0</parent>
      <child>link_1_clone_clone_0</child>
      <pose frame=''>0 0 0 0 -0 0</pose>
      <axis>
        <xyz>0 1 0</xyz>
        <use_parent_model_frame>0</use_parent_model_frame>
        <limit>
          <lower>-1.79769e+308</lower>
          <upper>1.79769e+308</upper>
          <effort>-1</effort>
          <velocity>-1</velocity>
        </limit>
        <dynamics>
          <spring_reference>0</spring_reference>
          <spring_stiffness>0</spring_stiffness>
          <damping>0</damping>
        </dynamics>
      </axis>
      <physics>
        <ode>
          <limit>
            <cfm>0</cfm>
            <erp>0.2</erp>
          </limit>
          <suspension>
            <cfm>0</cfm>
            <erp>0.2</erp>
          </suspension>
        </ode>
      </physics>
    </joint>
    <static>0</static>
    <allow_auto_disable>1</allow_auto_disable>
  </model>

  <model name='Building'>
    <pose frame=''>-1.11028 -1.8145 0 0 -0 0</pose>
    <link name='Door_0'>
      <collision name='Door_0_Collision'>
        <geometry>
          <box>
            <size>0.9 0.17 2</size>
          </box>
        </geometry>
        <pose frame=''>0 0 1 0 -0 0</pose>
      </collision>
      <visual name='Door_0_Visual'>
        <pose frame=''>0 0 1 0 -0 0</pose>
        <geometry>
          <box>
            <size>0.9 0.17 2</size>
          </box>
        </geometry>
        <material>
          <script>
            <uri>file://media/materials/scripts/gazebo.material</uri>
            <name>Gazebo/Grey</name>
          </script>
        </material>
      </visual>
      <pose frame=''>-28.7575 9.84664 0 0 -0 0</pose>
    </link>
    <link name='Door_1'>
      <collision name='Door_1_Collision'>
        <geometry>
          <box>
            <size>0.9 0.17 2</size>
          </box>
        </geometry>
        <pose frame=''>0 0 1 0 -0 0</pose>
      </collision>
      <visual name='Door_1_Visual'>
        <pose frame=''>0 0 1 0 -0 0</pose>
        <geometry>
          <box>
            <size>0.9 0.17 2</size>
          </box>
        </geometry>
        <material>
          <script>
            <uri>file://media/materials/scripts/gazebo.material</uri>
            <name>Gazebo/Grey</name>
          </script>
        </material>
      </visual>
      <pose frame=''>-15.1147 -9.07776 0 0 -0 0</pose>
    </link>
    <link name='Door_2'>
      <collision name='Door_2_Collision'>
        <geometry>
          <box>
            <size>0.9 0.17 2</size>
          </box>
        </geometry>
        <pose frame=''>0 0 1 0 -0 0</pose>
      </collision>
      <visual name='Door_2_Visual'>
        <pose frame=''>0 0 1 0 -0 0</pose>
        <geometry>
          <box>
            <size>0.9 0.17 2</size>
          </box>
        </geometry>
        <material>
          <script>
            <uri>file://media/materials/scripts/gazebo.material</uri>
            <name>Gazebo/Grey</name>
          </script>
        </material>
      </visual>
      <pose frame=''>-28.5663 2.5444 0 0 -0 0</pose>
    </link>
    <link name='Door_4'>
      <collision name='Door_4_Collision'>
        <geometry>
          <box>
            <size>0.9 0.17 2</size>
          </box>
        </geometry>
        <pose frame=''>0 0 1 0 -0 0</pose>
      </collision>
      <visual name='Door_4_Visual'>
        <pose frame=''>0 0 1 0 -0 0</pose>
        <geometry>
          <box>
            <size>0.9 0.17 2</size>
          </box>
        </geometry>
        <material>
          <script>
            <uri>file://media/materials/scripts/gazebo.material</uri>
            <name>Gazebo/Grey</name>
          </script>
        </material>
      </visual>
      <pose frame=''>28.2667 -1.23216 0 0 -0 0</pose>
    </link>
    <link name='Door_5'>
      <collision name='Door_5_Collision'>
        <geometry>
          <box>
            <size>0.9 0.17 2</size>
          </box>
        </geometry>
        <pose frame=''>0 0 1 0 -0 0</pose>
      </collision>
      <visual name='Door_5_Visual'>
        <pose frame=''>0 0 1 0 -0 0</pose>
        <geometry>
          <box>
            <size>0.9 0.17 2</size>
          </box>
        </geometry>
        <material>
          <script>
            <uri>file://media/materials/scripts/gazebo.material</uri>
            <name>Gazebo/Grey</name>
          </script>
        </material>
      </visual>
      <pose frame=''>16.8813 11.3908 0 0 -0 0</pose>
    </link>
    <link name='Wall_0'>
      <collision name='Wall_0_Collision'>
        <geometry>
          <box>
            <size>19.8005 0.15 2.5</size>
          </box>
        </geometry>
        <pose frame=''>0 0 1.25 0 -0 0</pose>
      </collision>
      <visual name='Wall_0_Visual'>
        <pose frame=''>0 0 1.25 0 -0 0</pose>
        <geometry>
          <box>
            <size>19.8005 0.15 2.5</size>
          </box>
        </geometry>
        <material>
          <script>
            <uri>file://media/materials/scripts/gazebo.material</uri>
            <name>Gazebo/Grey</name>
          </script>
          <ambient>0.435294 0.796078 0.67451 1</ambient>
        </material>
        <meta>
          <layer>0</layer>
        </meta>
      </visual>
      <pose frame=''>-29.1106 -1.17691 0 0 0 -1.5708</pose>
    </link>
    <link name='Wall_1'>
      <collision name='Wall_1_Collision'>
        <geometry>
          <box>
            <size>58.3767 0.15 2.5</size>
          </box>
        </geometry>
        <pose frame=''>0 0 1.25 0 -0 0</pose>
      </collision>
      <visual name='Wall_1_Visual'>
        <pose frame=''>0 0 1.25 0 -0 0</pose>
        <geometry>
          <box>
            <size>58.3767 0.15 2.5</size>
          </box>
        </geometry>
        <material>
          <script>
            <uri>file://media/materials/scripts/gazebo.material</uri>
            <name>Gazebo/Grey</name>
          </script>
          <ambient>0.435294 0.796078 0.67451 1</ambient>
        </material>
        <meta>
          <layer>0</layer>
        </meta>
      </visual>
      <pose frame=''>0 -11.524 0 0 0 -0.013673</pose>
    </link>
    <link name='Wall_12'>
      <collision name='Wall_12_Collision'>
        <geometry>
          <box>
            <size>2.5 0.15 2.5</size>
          </box>
        </geometry>
        <pose frame=''>0 0 1.25 0 -0 0</pose>
      </collision>
      <visual name='Wall_12_Visual'>
        <pose frame=''>0 0 1.25 0 -0 0</pose>
        <geometry>
          <box>
            <size>2.5 0.15 2.5</size>
          </box>
        </geometry>
        <material>
          <script>
            <uri>file://media/materials/scripts/gazebo.material</uri>
            <name>Gazebo/Grey</name>
          </script>
          <ambient>0.996078 0.47451 0.0196078 1</ambient>
        </material>
        <meta>
          <layer>0</layer>
        </meta>
      </visual>
      <pose frame=''>-26.5095 2.28662 0 0 -0 3.14159</pose>
    </link>
    <link name='Wall_14'>
      <collision name='Wall_14_Collision'>
        <geometry>
          <box>
            <size>0.25 0.15 2.5</size>
          </box>
        </geometry>
        <pose frame=''>0 0 1.25 0 -0 0</pose>
      </collision>
      <visual name='Wall_14_Visual'>
        <pose frame=''>0 0 1.25 0 -0 0</pose>
        <geometry>
          <box>
            <size>0.25 0.15 2.5</size>
          </box>
        </geometry>
        <material>
          <script>
            <uri>file://media/materials/scripts/gazebo.material</uri>
            <name>Gazebo/Grey</name>
          </script>
          <ambient>1 1 1 1</ambient>
        </material>
        <meta>
          <layer>0</layer>
        </meta>
      </visual>
      <pose frame=''>16.343 -1.08341 0 0 -0 2.61799</pose>
    </link>
    <link name='Wall_15'>
      <collision name='Wall_15_Collision'>
        <geometry>
          <box>
            <size>11.5 0.15 2.5</size>
          </box>
        </geometry>
        <pose frame=''>0 0 1.25 0 -0 0</pose>
      </collision>
      <visual name='Wall_15_Visual'>
        <pose frame=''>0 0 1.25 0 -0 0</pose>
        <geometry>
          <box>
            <size>11.5 0.15 2.5</size>
          </box>
        </geometry>
        <material>
          <script>
            <uri>file://media/materials/scripts/gazebo.material</uri>
            <name>Gazebo/Grey</name>
          </script>
          <ambient>0.996078 0.47451 0.0196078 1</ambient>
        </material>
        <meta>
          <layer>0</layer>
        </meta>
      </visual>
      <pose frame=''>21.9747 -1.05841 0 0 -0 0</pose>
    </link>
    <link name='Wall_17'>
      <collision name='Wall_17_Collision'>
        <geometry>
          <box>
            <size>11.5 0.15 2.5</size>
          </box>
        </geometry>
        <pose frame=''>0 0 1.25 0 -0 0</pose>
      </collision>
      <visual name='Wall_17_Visual'>
        <pose frame=''>0 0 1.25 0 -0 0</pose>
        <geometry>
          <box>
            <size>11.5 0.15 2.5</size>
          </box>
        </geometry>
        <material>
          <script>
            <uri>file://media/materials/scripts/gazebo.material</uri>
            <name>Gazebo/Grey</name>
          </script>
          <ambient>0.996078 0.47451 0.0196078 1</ambient>
        </material>
        <meta>
          <layer>0</layer>
        </meta>
      </visual>
      <pose frame=''>16.3863 4.56659 0 0 -0 1.5708</pose>
    </link>
    <link name='Wall_2'>
      <collision name='Wall_2_Collision'>
        <geometry>
          <box>
            <size>23.8713 0.15 2.5</size>
          </box>
        </geometry>
        <pose frame=''>0 0 1.25 0 -0 0</pose>
      </collision>
      <visual name='Wall_2_Visual'>
        <pose frame=''>0 0 1.25 0 -0 0</pose>
        <geometry>
          <box>
            <size>23.8713 0.15 2.5</size>
          </box>
        </geometry>
        <material>
          <script>
            <uri>file://media/materials/scripts/gazebo.material</uri>
            <name>Gazebo/Grey</name>
          </script>
          <ambient>0.435294 0.796078 0.67451 1</ambient>
        </material>
        <meta>
          <layer>0</layer>
        </meta>
      </visual>
      <pose frame=''>29.1106 0.062386 0 0 -0 1.5708</pose>
    </link>
    <link name='Wall_3'>
      <collision name='Wall_3_Collision'>
        <geometry>
          <box>
            <size>58.3714 0.15 2.5</size>
          </box>
        </geometry>
        <pose frame=''>0 0 1.25 0 -0 0</pose>
      </collision>
      <visual name='Wall_3_Visual'>
        <pose frame=''>0 0 1.25 0 -0 0</pose>
        <geometry>
          <box>
            <size>58.3714 0.15 2.5</size>
          </box>
        </geometry>
        <material>
          <script>
            <uri>file://media/materials/scripts/gazebo.material</uri>
            <name>Gazebo/Grey</name>
          </script>
          <ambient>0.435294 0.796078 0.67451 1</ambient>
        </material>
        <meta>
          <layer>0</layer>
        </meta>
      </visual>
      <pose frame=''>0 11.7993 0 0 -0 3.14159</pose>
    </link>
    <link name='Wall_4'>
      <collision name='Wall_4_Collision'>
        <geometry>
          <box>
            <size>2 0.15 2.5</size>
          </box>
        </geometry>
        <pose frame=''>0 0 1.25 0 -0 0</pose>
      </collision>
      <visual name='Wall_4_Visual'>
        <pose frame=''>0 0 1.25 0 -0 0</pose>
        <geometry>
          <box>
            <size>2 0.15 2.5</size>
          </box>
        </geometry>
        <material>
          <script>
            <uri>file://media/materials/scripts/gazebo.material</uri>
            <name>Gazebo/Grey</name>
          </script>
          <ambient>0.435294 0.796078 0.67451 1</ambient>
        </material>
        <meta>
          <layer>0</layer>
        </meta>
      </visual>
      <pose frame=''>-29.1106 10.8743 0 0 0 -1.5708</pose>
    </link>
    <link name='Wall_6'>
      <collision name='Wall_6_Collision'>
        <geometry>
          <box>
            <size>10 0.15 2.5</size>
          </box>
        </geometry>
        <pose frame=''>0 0 1.25 0 -0 0</pose>
      </collision>
      <visual name='Wall_6_Visual'>
        <pose frame=''>0 0 1.25 0 -0 0</pose>
        <geometry>
          <box>
            <size>10 0.15 2.5</size>
          </box>
        </geometry>
        <material>
          <script>
            <uri>file://media/materials/scripts/gazebo.material</uri>
            <name>Gazebo/Grey</name>
          </script>
          <ambient>0.996078 0.47451 0.0196078 1</ambient>
        </material>
        <meta>
          <layer>0</layer>
        </meta>
      </visual>
      <pose frame=''>-20.4095 2.28662 0 0 -0 0</pose>
    </link>
    <link name='Wall_7'>
      <collision name='Wall_7_Collision'>
        <geometry>
          <box>
            <size>11.3585 0.15 2.5</size>
          </box>
        </geometry>
        <pose frame=''>0 0 1.25 0 -0 0</pose>
      </collision>
      <visual name='Wall_7_Visual'>
        <pose frame=''>0 0 1.25 0 -0 0</pose>
        <geometry>
          <box>
            <size>11.3585 0.15 2.5</size>
          </box>
        </geometry>
        <material>
          <script>
            <uri>file://media/materials/scripts/gazebo.material</uri>
            <name>Gazebo/Grey</name>
          </script>
          <ambient>0.996078 0.47451 0.0196078 1</ambient>
        </material>
        <meta>
          <layer>0</layer>
        </meta>
      </visual>
      <pose frame=''>-15.4845 -3.31763 0 0 0 -1.5708</pose>
    </link>
    <link name='Wall_9'>
      <collision name='Wall_9_Collision'>
        <geometry>
          <box>
            <size>1 0.15 2.5</size>
          </box>
        </geometry>
        <pose frame=''>0 0 1.25 0 -0 0</pose>
      </collision>
      <visual name='Wall_9_Visual'>
        <pose frame=''>0 0 1.25 0 -0 0</pose>
        <geometry>
          <box>
            <size>1 0.15 2.5</size>
          </box>
        </geometry>
        <material>
          <script>
            <uri>file://media/materials/scripts/gazebo.material</uri>
            <name>Gazebo/Grey</name>
          </script>
          <ambient>0.996078 0.47451 0.0196078 1</ambient>
        </material>
        <meta>
          <layer>0</layer>
        </meta>
      </visual>
      <pose frame=''>-15.4375 -10.805 0 0 -0 1.5708</pose>
    </link>
    <static>1</static>
  </model>

    <include>
        <uri>model://table</uri>
        <pose>-4 -5 0 0 0 0</pose>
    </include>
  </world>
</sdf>
